2025-05-22 04:51:38,390 1 INFO ? odoo: Odoo version 18.0-20250520 
2025-05-22 04:51:38,391 1 INFO ? odoo: Using configuration file at /etc/odoo/odoo.conf 
2025-05-22 04:51:38,391 1 INFO ? odoo: addons paths: ['/usr/lib/python3/dist-packages/odoo/addons', '/var/lib/odoo/addons/18.0', '/mnt/extra-addons'] 
2025-05-22 04:51:38,391 1 INFO ? odoo: database: odoo@db:5432 
2025-05-22 04:51:38,572 1 INFO ? odoo.addons.base.models.ir_actions_report: Will use the Wkhtmltopdf binary at /usr/local/bin/wkhtmltopdf 
2025-05-22 04:51:38,586 1 INFO ? odoo.addons.base.models.ir_actions_report: Will use the Wkhtmltoimage binary at /usr/local/bin/wkhtmltoimage 
2025-05-22 04:51:38,728 1 INFO ? odoo.service.server: HTTP service (werkzeug) running on 4ce19f4768cc:8069 
2025-05-22 04:51:53,849 1 INFO ? odoo.service.server: Initiating shutdown 
2025-05-22 04:51:53,849 1 INFO ? odoo.service.server: Hit CTRL-C again or send a second signal to force the shutdown. 
2025-05-22 04:51:54,240 1 INFO ? odoo.sql_db: ConnectionPool(read/write;used=0/count=0/max=64): Closed 2 connections  
2025-05-22 04:51:56,174 1 INFO ? odoo: Odoo version 18.0-20250520 
2025-05-22 04:51:56,175 1 INFO ? odoo: Using configuration file at /etc/odoo/odoo.conf 
2025-05-22 04:51:56,175 1 INFO ? odoo: addons paths: ['/usr/lib/python3/dist-packages/odoo/addons', '/var/lib/odoo/addons/18.0', '/mnt/extra-addons'] 
2025-05-22 04:51:56,175 1 INFO ? odoo: database: odoo@db:5432 
2025-05-22 04:51:57,050 1 INFO ? odoo.addons.base.models.ir_actions_report: Will use the Wkhtmltopdf binary at /usr/local/bin/wkhtmltopdf 
2025-05-22 04:51:57,056 1 INFO ? odoo.addons.base.models.ir_actions_report: Will use the Wkhtmltoimage binary at /usr/local/bin/wkhtmltoimage 
2025-05-22 04:51:57,193 1 INFO ? odoo.service.server: HTTP service (werkzeug) running on 4ce19f4768cc:8069 
2025-05-22 04:52:03,258 1 ERROR ? odoo.modules.loading: Database odoo not initialized, you can force it with `-i base` 
2025-05-22 04:52:03,259 1 INFO ? odoo.modules.registry: Registry loaded in 0.021s 
2025-05-22 04:52:03,260 1 ERROR odoo odoo.http: Exception during request handling. 
Traceback (most recent call last):
  File "/usr/lib/python3/dist-packages/odoo/http.py", line 2386, in __call__
    response = request._serve_db()
               ^^^^^^^^^^^^^^^^^^^
  File "/usr/lib/python3/dist-packages/odoo/http.py", line 1894, in _serve_db
    rule, args = self.registry['ir.http']._match(self.httprequest.path)
                 ~~~~~~~~~~~~~^^^^^^^^^^^
  File "/usr/lib/python3/dist-packages/odoo/modules/registry.py", line 240, in __getitem__
    return self.models[model_name]
           ~~~~~~~~~~~^^^^^^^^^^^^
KeyError: 'ir.http'
2025-05-22 04:52:03,262 1 INFO odoo werkzeug: 172.18.0.1 - - [22/May/2025 04:52:03] "GET / HTTP/1.1" 500 - 20 0.011 0.026
2025-05-22 04:52:03,298 1 ERROR odoo odoo.http: Exception during request handling. 
Traceback (most recent call last):
  File "/usr/lib/python3/dist-packages/odoo/http.py", line 2386, in __call__
    response = request._serve_db()
               ^^^^^^^^^^^^^^^^^^^
  File "/usr/lib/python3/dist-packages/odoo/http.py", line 1894, in _serve_db
    rule, args = self.registry['ir.http']._match(self.httprequest.path)
                 ~~~~~~~~~~~~~^^^^^^^^^^^
  File "/usr/lib/python3/dist-packages/odoo/modules/registry.py", line 240, in __getitem__
    return self.models[model_name]
           ~~~~~~~~~~~^^^^^^^^^^^^
KeyError: 'ir.http'
2025-05-22 04:52:03,299 1 INFO odoo werkzeug: 172.18.0.1 - - [22/May/2025 04:52:03] "GET /favicon.ico HTTP/1.1" 500 - 2 0.002 0.009
2025-05-22 04:52:48,231 1 INFO ? odoo.service.server: Initiating shutdown 
2025-05-22 04:52:48,232 1 INFO ? odoo.service.server: Hit CTRL-C again or send a second signal to force the shutdown. 
2025-05-22 04:52:48,607 1 INFO ? odoo.sql_db: ConnectionPool(read/write;used=0/count=0/max=64): Closed 3 connections  
2025-05-22 04:54:40,865 1 INFO ? odoo: Odoo version 18.0-20250520 
2025-05-22 04:54:40,866 1 INFO ? odoo: Using configuration file at /etc/odoo/odoo.conf 
2025-05-22 04:54:40,867 1 INFO ? odoo: addons paths: ['/usr/lib/python3/dist-packages/odoo/addons', '/var/lib/odoo/addons/18.0', '/mnt/extra-addons'] 
2025-05-22 04:54:40,867 1 INFO ? odoo: database: odoo@db:5432 
2025-05-22 04:54:41,047 1 INFO ? odoo.addons.base.models.ir_actions_report: Will use the Wkhtmltopdf binary at /usr/local/bin/wkhtmltopdf 
2025-05-22 04:54:41,054 1 INFO ? odoo.addons.base.models.ir_actions_report: Will use the Wkhtmltoimage binary at /usr/local/bin/wkhtmltoimage 
2025-05-22 04:54:41,195 1 INFO ? odoo.service.server: HTTP service (werkzeug) running on 4ce19f4768cc:8069 
2025-05-22 04:54:45,581 1 ERROR ? odoo.modules.loading: Database odoo not initialized, you can force it with `-i base` 
2025-05-22 04:54:45,582 1 INFO ? odoo.modules.registry: Registry loaded in 0.016s 
2025-05-22 04:54:45,583 1 ERROR odoo odoo.http: Exception during request handling. 
Traceback (most recent call last):
  File "/usr/lib/python3/dist-packages/odoo/http.py", line 2386, in __call__
    response = request._serve_db()
               ^^^^^^^^^^^^^^^^^^^
  File "/usr/lib/python3/dist-packages/odoo/http.py", line 1894, in _serve_db
    rule, args = self.registry['ir.http']._match(self.httprequest.path)
                 ~~~~~~~~~~~~~^^^^^^^^^^^
  File "/usr/lib/python3/dist-packages/odoo/modules/registry.py", line 240, in __getitem__
    return self.models[model_name]
           ~~~~~~~~~~~^^^^^^^^^^^^
KeyError: 'ir.http'
2025-05-22 04:54:45,585 1 INFO odoo werkzeug: 172.18.0.1 - - [22/May/2025 04:54:45] "GET / HTTP/1.1" 500 - 8 0.008 0.023
2025-05-22 04:54:45,630 1 ERROR odoo odoo.http: Exception during request handling. 
Traceback (most recent call last):
  File "/usr/lib/python3/dist-packages/odoo/http.py", line 2386, in __call__
    response = request._serve_db()
               ^^^^^^^^^^^^^^^^^^^
  File "/usr/lib/python3/dist-packages/odoo/http.py", line 1894, in _serve_db
    rule, args = self.registry['ir.http']._match(self.httprequest.path)
                 ~~~~~~~~~~~~~^^^^^^^^^^^
  File "/usr/lib/python3/dist-packages/odoo/modules/registry.py", line 240, in __getitem__
    return self.models[model_name]
           ~~~~~~~~~~~^^^^^^^^^^^^
KeyError: 'ir.http'
2025-05-22 04:54:45,631 1 INFO odoo werkzeug: 172.18.0.1 - - [22/May/2025 04:54:45] "GET /favicon.ico HTTP/1.1" 500 - 2 0.002 0.010
2025-05-22 04:54:56,009 1 ERROR odoo odoo.http: Exception during request handling. 
Traceback (most recent call last):
  File "/usr/lib/python3/dist-packages/odoo/http.py", line 2386, in __call__
    response = request._serve_db()
               ^^^^^^^^^^^^^^^^^^^
  File "/usr/lib/python3/dist-packages/odoo/http.py", line 1894, in _serve_db
    rule, args = self.registry['ir.http']._match(self.httprequest.path)
                 ~~~~~~~~~~~~~^^^^^^^^^^^
  File "/usr/lib/python3/dist-packages/odoo/modules/registry.py", line 240, in __getitem__
    return self.models[model_name]
           ~~~~~~~~~~~^^^^^^^^^^^^
KeyError: 'ir.http'
2025-05-22 04:54:56,010 1 INFO odoo werkzeug: 172.18.0.1 - - [22/May/2025 04:54:56] "GET / HTTP/1.1" 500 - 2 0.002 0.008
2025-05-22 04:54:56,033 1 ERROR odoo odoo.http: Exception during request handling. 
Traceback (most recent call last):
  File "/usr/lib/python3/dist-packages/odoo/http.py", line 2386, in __call__
    response = request._serve_db()
               ^^^^^^^^^^^^^^^^^^^
  File "/usr/lib/python3/dist-packages/odoo/http.py", line 1894, in _serve_db
    rule, args = self.registry['ir.http']._match(self.httprequest.path)
                 ~~~~~~~~~~~~~^^^^^^^^^^^
  File "/usr/lib/python3/dist-packages/odoo/modules/registry.py", line 240, in __getitem__
    return self.models[model_name]
           ~~~~~~~~~~~^^^^^^^^^^^^
KeyError: 'ir.http'
2025-05-22 04:54:56,034 1 INFO odoo werkzeug: 172.18.0.1 - - [22/May/2025 04:54:56] "GET /favicon.ico HTTP/1.1" 500 - 2 0.002 0.009
2025-05-22 04:55:43,944 1 ERROR odoo odoo.sql_db: bad query: b"\n            SELECT latest_version\n            FROM ir_module_module\n             WHERE name='base'\n        "
ERROR: relation "ir_module_module" does not exist
LINE 3:             FROM ir_module_module
                         ^
 
2025-05-22 04:55:43,945 1 WARNING odoo odoo.addons.base.models.ir_cron: Tried to poll an undefined table on database odoo. 
2025-05-22 04:55:44,956 1 ERROR odoo odoo.sql_db: bad query: b"\n            SELECT latest_version\n            FROM ir_module_module\n             WHERE name='base'\n        "
ERROR: relation "ir_module_module" does not exist
LINE 3:             FROM ir_module_module
                         ^
 
2025-05-22 04:55:44,957 1 WARNING odoo odoo.addons.base.models.ir_cron: Tried to poll an undefined table on database odoo. 
2025-05-22 04:56:46,654 1 ERROR odoo odoo.sql_db: bad query: b"\n            SELECT latest_version\n            FROM ir_module_module\n             WHERE name='base'\n        "
ERROR: relation "ir_module_module" does not exist
LINE 3:             FROM ir_module_module
                         ^
 
2025-05-22 04:56:46,655 1 WARNING odoo odoo.addons.base.models.ir_cron: Tried to poll an undefined table on database odoo. 
2025-05-22 04:56:48,679 1 ERROR odoo odoo.sql_db: bad query: b"\n            SELECT latest_version\n            FROM ir_module_module\n             WHERE name='base'\n        "
ERROR: relation "ir_module_module" does not exist
LINE 3:             FROM ir_module_module
                         ^
 
2025-05-22 04:56:48,680 1 WARNING odoo odoo.addons.base.models.ir_cron: Tried to poll an undefined table on database odoo. 
2025-05-22 04:57:49,338 1 ERROR odoo odoo.sql_db: bad query: b"\n            SELECT latest_version\n            FROM ir_module_module\n             WHERE name='base'\n        "
ERROR: relation "ir_module_module" does not exist
LINE 3:             FROM ir_module_module
                         ^
 
2025-05-22 04:57:49,339 1 WARNING odoo odoo.addons.base.models.ir_cron: Tried to poll an undefined table on database odoo. 
2025-05-22 04:57:52,427 1 ERROR odoo odoo.sql_db: bad query: b"\n            SELECT latest_version\n            FROM ir_module_module\n             WHERE name='base'\n        "
ERROR: relation "ir_module_module" does not exist
LINE 3:             FROM ir_module_module
                         ^
 
2025-05-22 04:57:52,427 1 WARNING odoo odoo.addons.base.models.ir_cron: Tried to poll an undefined table on database odoo. 
2025-05-22 04:58:51,996 1 ERROR odoo odoo.sql_db: bad query: b"\n            SELECT latest_version\n            FROM ir_module_module\n             WHERE name='base'\n        "
ERROR: relation "ir_module_module" does not exist
LINE 3:             FROM ir_module_module
                         ^
 
2025-05-22 04:58:51,997 1 WARNING odoo odoo.addons.base.models.ir_cron: Tried to poll an undefined table on database odoo. 
2025-05-22 04:58:56,133 1 ERROR odoo odoo.sql_db: bad query: b"\n            SELECT latest_version\n            FROM ir_module_module\n             WHERE name='base'\n        "
ERROR: relation "ir_module_module" does not exist
LINE 3:             FROM ir_module_module
                         ^
 
2025-05-22 04:58:56,134 1 WARNING odoo odoo.addons.base.models.ir_cron: Tried to poll an undefined table on database odoo. 
2025-05-22 04:59:54,717 1 ERROR odoo odoo.sql_db: bad query: b"\n            SELECT latest_version\n            FROM ir_module_module\n             WHERE name='base'\n        "
ERROR: relation "ir_module_module" does not exist
LINE 3:             FROM ir_module_module
                         ^
 
2025-05-22 04:59:54,717 1 WARNING odoo odoo.addons.base.models.ir_cron: Tried to poll an undefined table on database odoo. 
2025-05-22 04:59:59,822 1 ERROR odoo odoo.sql_db: bad query: b"\n            SELECT latest_version\n            FROM ir_module_module\n             WHERE name='base'\n        "
ERROR: relation "ir_module_module" does not exist
LINE 3:             FROM ir_module_module
                         ^
 
2025-05-22 04:59:59,823 1 WARNING odoo odoo.addons.base.models.ir_cron: Tried to poll an undefined table on database odoo. 
2025-05-22 05:00:57,412 1 ERROR odoo odoo.sql_db: bad query: b"\n            SELECT latest_version\n            FROM ir_module_module\n             WHERE name='base'\n        "
ERROR: relation "ir_module_module" does not exist
LINE 3:             FROM ir_module_module
                         ^
 
2025-05-22 05:00:57,413 1 WARNING odoo odoo.addons.base.models.ir_cron: Tried to poll an undefined table on database odoo. 
2025-05-22 05:01:03,522 1 ERROR odoo odoo.sql_db: bad query: b"\n            SELECT latest_version\n            FROM ir_module_module\n             WHERE name='base'\n        "
ERROR: relation "ir_module_module" does not exist
LINE 3:             FROM ir_module_module
                         ^
 
2025-05-22 05:01:03,523 1 WARNING odoo odoo.addons.base.models.ir_cron: Tried to poll an undefined table on database odoo. 
2025-05-22 05:02:00,113 1 ERROR odoo odoo.sql_db: bad query: b"\n            SELECT latest_version\n            FROM ir_module_module\n             WHERE name='base'\n        "
ERROR: relation "ir_module_module" does not exist
LINE 3:             FROM ir_module_module
                         ^
 
2025-05-22 05:02:00,114 1 WARNING odoo odoo.addons.base.models.ir_cron: Tried to poll an undefined table on database odoo. 
2025-05-22 05:02:07,190 1 INFO ? odoo.service.server: Initiating shutdown 
2025-05-22 05:02:07,191 1 ERROR odoo odoo.sql_db: bad query: b"\n            SELECT latest_version\n            FROM ir_module_module\n             WHERE name='base'\n        "
ERROR: relation "ir_module_module" does not exist
LINE 3:             FROM ir_module_module
                         ^
 
2025-05-22 05:02:07,191 1 INFO ? odoo.service.server: Hit CTRL-C again or send a second signal to force the shutdown. 
2025-05-22 05:02:07,191 1 WARNING odoo odoo.addons.base.models.ir_cron: Tried to poll an undefined table on database odoo. 
2025-05-22 05:02:07,473 1 INFO ? odoo.sql_db: ConnectionPool(read/write;used=0/count=0/max=64): Closed 3 connections  
2025-05-22 05:02:08,771 1 INFO ? odoo: Odoo version 18.0-20250520 
2025-05-22 05:02:08,772 1 INFO ? odoo: Using configuration file at /etc/odoo/odoo.conf 
2025-05-22 05:02:08,772 1 INFO ? odoo: addons paths: ['/usr/lib/python3/dist-packages/odoo/addons', '/var/lib/odoo/addons/18.0', '/mnt/extra-addons'] 
2025-05-22 05:02:08,773 1 INFO ? odoo: database: odoo@db:5432 
2025-05-22 05:02:08,960 1 INFO ? odoo.addons.base.models.ir_actions_report: Will use the Wkhtmltopdf binary at /usr/local/bin/wkhtmltopdf 
2025-05-22 05:02:08,966 1 INFO ? odoo.addons.base.models.ir_actions_report: Will use the Wkhtmltoimage binary at /usr/local/bin/wkhtmltoimage 
2025-05-22 05:02:09,099 1 INFO ? odoo.service.server: HTTP service (werkzeug) running on 4ce19f4768cc:8069 
2025-05-22 05:02:21,781 1 INFO ? odoo.service.server: Initiating shutdown 
2025-05-22 05:02:21,781 1 INFO ? odoo.service.server: Hit CTRL-C again or send a second signal to force the shutdown. 
2025-05-22 05:02:22,746 1 INFO ? odoo.sql_db: ConnectionPool(read/write;used=0/count=0/max=64): Closed 2 connections  
2025-05-22 05:02:24,700 1 INFO ? odoo: Odoo version 18.0-20250520 
2025-05-22 05:02:24,701 1 INFO ? odoo: Using configuration file at /etc/odoo/odoo.conf 
2025-05-22 05:02:24,701 1 INFO ? odoo: addons paths: ['/usr/lib/python3/dist-packages/odoo/addons', '/var/lib/odoo/addons/18.0', '/mnt/extra-addons'] 
2025-05-22 05:02:24,701 1 INFO ? odoo: database: odoo@db:5432 
2025-05-22 05:02:24,875 1 INFO ? odoo.addons.base.models.ir_actions_report: Will use the Wkhtmltopdf binary at /usr/local/bin/wkhtmltopdf 
2025-05-22 05:02:24,882 1 INFO ? odoo.addons.base.models.ir_actions_report: Will use the Wkhtmltoimage binary at /usr/local/bin/wkhtmltoimage 
2025-05-22 05:02:25,013 1 INFO ? odoo.service.server: HTTP service (werkzeug) running on 4ce19f4768cc:8069 
2025-05-22 05:02:50,160 1 INFO ? odoo.service.server: Initiating shutdown 
2025-05-22 05:02:50,161 1 INFO ? odoo.service.server: Hit CTRL-C again or send a second signal to force the shutdown. 
2025-05-22 05:02:50,532 1 INFO ? odoo.sql_db: ConnectionPool(read/write;used=0/count=0/max=64): Closed 2 connections  
2025-05-22 05:02:51,883 1 INFO ? odoo: Odoo version 18.0-20250520 
2025-05-22 05:02:51,884 1 INFO ? odoo: Using configuration file at /etc/odoo/odoo.conf 
2025-05-22 05:02:51,884 1 INFO ? odoo: addons paths: ['/usr/lib/python3/dist-packages/odoo/addons', '/var/lib/odoo/addons/18.0', '/mnt/extra-addons'] 
2025-05-22 05:02:51,885 1 INFO ? odoo: database: odoo@db:5432 
2025-05-22 05:02:52,063 1 INFO ? odoo.addons.base.models.ir_actions_report: Will use the Wkhtmltopdf binary at /usr/local/bin/wkhtmltopdf 
2025-05-22 05:02:52,070 1 INFO ? odoo.addons.base.models.ir_actions_report: Will use the Wkhtmltoimage binary at /usr/local/bin/wkhtmltoimage 
2025-05-22 05:02:52,197 1 INFO ? odoo.service.server: HTTP service (werkzeug) running on 4ce19f4768cc:8069 
2025-05-22 05:03:17,325 1 ERROR ? odoo.modules.loading: Database odoo not initialized, you can force it with `-i base` 
2025-05-22 05:03:17,326 1 INFO ? odoo.modules.registry: Registry loaded in 0.013s 
2025-05-22 05:03:17,327 1 ERROR odoo odoo.http: Exception during request handling. 
Traceback (most recent call last):
  File "/usr/lib/python3/dist-packages/odoo/http.py", line 2386, in __call__
    response = request._serve_db()
               ^^^^^^^^^^^^^^^^^^^
  File "/usr/lib/python3/dist-packages/odoo/http.py", line 1894, in _serve_db
    rule, args = self.registry['ir.http']._match(self.httprequest.path)
                 ~~~~~~~~~~~~~^^^^^^^^^^^
  File "/usr/lib/python3/dist-packages/odoo/modules/registry.py", line 240, in __getitem__
    return self.models[model_name]
           ~~~~~~~~~~~^^^^^^^^^^^^
KeyError: 'ir.http'
2025-05-22 05:03:17,328 1 INFO odoo werkzeug: 172.18.0.1 - - [22/May/2025 05:03:17] "GET / HTTP/1.1" 500 - 8 0.008 0.019
2025-05-22 05:03:17,365 1 ERROR odoo odoo.http: Exception during request handling. 
Traceback (most recent call last):
  File "/usr/lib/python3/dist-packages/odoo/http.py", line 2386, in __call__
    response = request._serve_db()
               ^^^^^^^^^^^^^^^^^^^
  File "/usr/lib/python3/dist-packages/odoo/http.py", line 1894, in _serve_db
    rule, args = self.registry['ir.http']._match(self.httprequest.path)
                 ~~~~~~~~~~~~~^^^^^^^^^^^
  File "/usr/lib/python3/dist-packages/odoo/modules/registry.py", line 240, in __getitem__
    return self.models[model_name]
           ~~~~~~~~~~~^^^^^^^^^^^^
KeyError: 'ir.http'
2025-05-22 05:03:17,366 1 INFO odoo werkzeug: 172.18.0.1 - - [22/May/2025 05:03:17] "GET /favicon.ico HTTP/1.1" 500 - 2 0.002 0.009
2025-05-22 05:03:54,856 1 ERROR odoo odoo.sql_db: bad query: b"\n            SELECT latest_version\n            FROM ir_module_module\n             WHERE name='base'\n        "
ERROR: relation "ir_module_module" does not exist
LINE 3:             FROM ir_module_module
                         ^
 
2025-05-22 05:03:54,857 1 WARNING odoo odoo.addons.base.models.ir_cron: Tried to poll an undefined table on database odoo. 
2025-05-22 05:03:55,918 1 ERROR odoo odoo.sql_db: bad query: b"\n            SELECT latest_version\n            FROM ir_module_module\n             WHERE name='base'\n        "
ERROR: relation "ir_module_module" does not exist
LINE 3:             FROM ir_module_module
                         ^
 
2025-05-22 05:03:55,919 1 WARNING odoo odoo.addons.base.models.ir_cron: Tried to poll an undefined table on database odoo. 
2025-05-22 05:04:01,597 1 ERROR odoo odoo.http: Exception during request handling. 
Traceback (most recent call last):
  File "/usr/lib/python3/dist-packages/odoo/http.py", line 2386, in __call__
    response = request._serve_db()
               ^^^^^^^^^^^^^^^^^^^
  File "/usr/lib/python3/dist-packages/odoo/http.py", line 1894, in _serve_db
    rule, args = self.registry['ir.http']._match(self.httprequest.path)
                 ~~~~~~~~~~~~~^^^^^^^^^^^
  File "/usr/lib/python3/dist-packages/odoo/modules/registry.py", line 240, in __getitem__
    return self.models[model_name]
           ~~~~~~~~~~~^^^^^^^^^^^^
KeyError: 'ir.http'
2025-05-22 05:04:01,599 1 INFO odoo werkzeug: 172.18.0.1 - - [22/May/2025 05:04:01] "GET / HTTP/1.1" 500 - 2 0.002 0.009
2025-05-22 05:04:01,638 1 ERROR odoo odoo.http: Exception during request handling. 
Traceback (most recent call last):
  File "/usr/lib/python3/dist-packages/odoo/http.py", line 2386, in __call__
    response = request._serve_db()
               ^^^^^^^^^^^^^^^^^^^
  File "/usr/lib/python3/dist-packages/odoo/http.py", line 1894, in _serve_db
    rule, args = self.registry['ir.http']._match(self.httprequest.path)
                 ~~~~~~~~~~~~~^^^^^^^^^^^
  File "/usr/lib/python3/dist-packages/odoo/modules/registry.py", line 240, in __getitem__
    return self.models[model_name]
           ~~~~~~~~~~~^^^^^^^^^^^^
KeyError: 'ir.http'
2025-05-22 05:04:01,639 1 INFO odoo werkzeug: 172.18.0.1 - - [22/May/2025 05:04:01] "GET /favicon.ico HTTP/1.1" 500 - 2 0.002 0.009
2025-05-22 05:04:02,980 1 ERROR odoo odoo.http: Exception during request handling. 
Traceback (most recent call last):
  File "/usr/lib/python3/dist-packages/odoo/http.py", line 2386, in __call__
    response = request._serve_db()
               ^^^^^^^^^^^^^^^^^^^
  File "/usr/lib/python3/dist-packages/odoo/http.py", line 1894, in _serve_db
    rule, args = self.registry['ir.http']._match(self.httprequest.path)
                 ~~~~~~~~~~~~~^^^^^^^^^^^
  File "/usr/lib/python3/dist-packages/odoo/modules/registry.py", line 240, in __getitem__
    return self.models[model_name]
           ~~~~~~~~~~~^^^^^^^^^^^^
KeyError: 'ir.http'
2025-05-22 05:04:02,981 1 INFO odoo werkzeug: 172.18.0.1 - - [22/May/2025 05:04:02] "GET / HTTP/1.1" 500 - 2 0.001 0.009
2025-05-22 05:04:03,006 1 ERROR odoo odoo.http: Exception during request handling. 
Traceback (most recent call last):
  File "/usr/lib/python3/dist-packages/odoo/http.py", line 2386, in __call__
    response = request._serve_db()
               ^^^^^^^^^^^^^^^^^^^
  File "/usr/lib/python3/dist-packages/odoo/http.py", line 1894, in _serve_db
    rule, args = self.registry['ir.http']._match(self.httprequest.path)
                 ~~~~~~~~~~~~~^^^^^^^^^^^
  File "/usr/lib/python3/dist-packages/odoo/modules/registry.py", line 240, in __getitem__
    return self.models[model_name]
           ~~~~~~~~~~~^^^^^^^^^^^^
KeyError: 'ir.http'
2025-05-22 05:04:03,007 1 INFO odoo werkzeug: 172.18.0.1 - - [22/May/2025 05:04:03] "GET /favicon.ico HTTP/1.1" 500 - 2 0.002 0.008
2025-05-22 05:04:03,169 1 ERROR odoo odoo.http: Exception during request handling. 
Traceback (most recent call last):
  File "/usr/lib/python3/dist-packages/odoo/http.py", line 2386, in __call__
    response = request._serve_db()
               ^^^^^^^^^^^^^^^^^^^
  File "/usr/lib/python3/dist-packages/odoo/http.py", line 1894, in _serve_db
    rule, args = self.registry['ir.http']._match(self.httprequest.path)
                 ~~~~~~~~~~~~~^^^^^^^^^^^
  File "/usr/lib/python3/dist-packages/odoo/modules/registry.py", line 240, in __getitem__
    return self.models[model_name]
           ~~~~~~~~~~~^^^^^^^^^^^^
KeyError: 'ir.http'
2025-05-22 05:04:03,170 1 INFO odoo werkzeug: 172.18.0.1 - - [22/May/2025 05:04:03] "GET / HTTP/1.1" 500 - 2 0.002 0.008
2025-05-22 05:04:03,194 1 ERROR odoo odoo.http: Exception during request handling. 
Traceback (most recent call last):
  File "/usr/lib/python3/dist-packages/odoo/http.py", line 2386, in __call__
    response = request._serve_db()
               ^^^^^^^^^^^^^^^^^^^
  File "/usr/lib/python3/dist-packages/odoo/http.py", line 1894, in _serve_db
    rule, args = self.registry['ir.http']._match(self.httprequest.path)
                 ~~~~~~~~~~~~~^^^^^^^^^^^
  File "/usr/lib/python3/dist-packages/odoo/modules/registry.py", line 240, in __getitem__
    return self.models[model_name]
           ~~~~~~~~~~~^^^^^^^^^^^^
KeyError: 'ir.http'
2025-05-22 05:04:03,195 1 INFO odoo werkzeug: 172.18.0.1 - - [22/May/2025 05:04:03] "GET /favicon.ico HTTP/1.1" 500 - 2 0.002 0.008
2025-05-22 05:04:03,328 1 ERROR odoo odoo.http: Exception during request handling. 
Traceback (most recent call last):
  File "/usr/lib/python3/dist-packages/odoo/http.py", line 2386, in __call__
    response = request._serve_db()
               ^^^^^^^^^^^^^^^^^^^
  File "/usr/lib/python3/dist-packages/odoo/http.py", line 1894, in _serve_db
    rule, args = self.registry['ir.http']._match(self.httprequest.path)
                 ~~~~~~~~~~~~~^^^^^^^^^^^
  File "/usr/lib/python3/dist-packages/odoo/modules/registry.py", line 240, in __getitem__
    return self.models[model_name]
           ~~~~~~~~~~~^^^^^^^^^^^^
KeyError: 'ir.http'
2025-05-22 05:04:03,328 1 INFO odoo werkzeug: 172.18.0.1 - - [22/May/2025 05:04:03] "GET / HTTP/1.1" 500 - 2 0.002 0.008
2025-05-22 05:04:03,353 1 ERROR odoo odoo.http: Exception during request handling. 
Traceback (most recent call last):
  File "/usr/lib/python3/dist-packages/odoo/http.py", line 2386, in __call__
    response = request._serve_db()
               ^^^^^^^^^^^^^^^^^^^
  File "/usr/lib/python3/dist-packages/odoo/http.py", line 1894, in _serve_db
    rule, args = self.registry['ir.http']._match(self.httprequest.path)
                 ~~~~~~~~~~~~~^^^^^^^^^^^
  File "/usr/lib/python3/dist-packages/odoo/modules/registry.py", line 240, in __getitem__
    return self.models[model_name]
           ~~~~~~~~~~~^^^^^^^^^^^^
KeyError: 'ir.http'
2025-05-22 05:04:03,354 1 INFO odoo werkzeug: 172.18.0.1 - - [22/May/2025 05:04:03] "GET /favicon.ico HTTP/1.1" 500 - 2 0.002 0.008
2025-05-22 05:04:03,700 1 ERROR odoo odoo.http: Exception during request handling. 
Traceback (most recent call last):
  File "/usr/lib/python3/dist-packages/odoo/http.py", line 2386, in __call__
    response = request._serve_db()
               ^^^^^^^^^^^^^^^^^^^
  File "/usr/lib/python3/dist-packages/odoo/http.py", line 1894, in _serve_db
    rule, args = self.registry['ir.http']._match(self.httprequest.path)
                 ~~~~~~~~~~~~~^^^^^^^^^^^
  File "/usr/lib/python3/dist-packages/odoo/modules/registry.py", line 240, in __getitem__
    return self.models[model_name]
           ~~~~~~~~~~~^^^^^^^^^^^^
KeyError: 'ir.http'
2025-05-22 05:04:03,701 1 INFO odoo werkzeug: 172.18.0.1 - - [22/May/2025 05:04:03] "GET / HTTP/1.1" 500 - 2 0.002 0.008
2025-05-22 05:04:03,729 1 ERROR odoo odoo.http: Exception during request handling. 
Traceback (most recent call last):
  File "/usr/lib/python3/dist-packages/odoo/http.py", line 2386, in __call__
    response = request._serve_db()
               ^^^^^^^^^^^^^^^^^^^
  File "/usr/lib/python3/dist-packages/odoo/http.py", line 1894, in _serve_db
    rule, args = self.registry['ir.http']._match(self.httprequest.path)
                 ~~~~~~~~~~~~~^^^^^^^^^^^
  File "/usr/lib/python3/dist-packages/odoo/modules/registry.py", line 240, in __getitem__
    return self.models[model_name]
           ~~~~~~~~~~~^^^^^^^^^^^^
KeyError: 'ir.http'
2025-05-22 05:04:03,730 1 INFO odoo werkzeug: 172.18.0.1 - - [22/May/2025 05:04:03] "GET /favicon.ico HTTP/1.1" 500 - 2 0.002 0.008
2025-05-22 05:04:03,874 1 ERROR odoo odoo.http: Exception during request handling. 
Traceback (most recent call last):
  File "/usr/lib/python3/dist-packages/odoo/http.py", line 2386, in __call__
    response = request._serve_db()
               ^^^^^^^^^^^^^^^^^^^
  File "/usr/lib/python3/dist-packages/odoo/http.py", line 1894, in _serve_db
    rule, args = self.registry['ir.http']._match(self.httprequest.path)
                 ~~~~~~~~~~~~~^^^^^^^^^^^
  File "/usr/lib/python3/dist-packages/odoo/modules/registry.py", line 240, in __getitem__
    return self.models[model_name]
           ~~~~~~~~~~~^^^^^^^^^^^^
KeyError: 'ir.http'
2025-05-22 05:04:03,875 1 INFO odoo werkzeug: 172.18.0.1 - - [22/May/2025 05:04:03] "GET / HTTP/1.1" 500 - 2 0.002 0.008
2025-05-22 05:04:03,900 1 ERROR odoo odoo.http: Exception during request handling. 
Traceback (most recent call last):
  File "/usr/lib/python3/dist-packages/odoo/http.py", line 2386, in __call__
    response = request._serve_db()
               ^^^^^^^^^^^^^^^^^^^
  File "/usr/lib/python3/dist-packages/odoo/http.py", line 1894, in _serve_db
    rule, args = self.registry['ir.http']._match(self.httprequest.path)
                 ~~~~~~~~~~~~~^^^^^^^^^^^
  File "/usr/lib/python3/dist-packages/odoo/modules/registry.py", line 240, in __getitem__
    return self.models[model_name]
           ~~~~~~~~~~~^^^^^^^^^^^^
KeyError: 'ir.http'
2025-05-22 05:04:03,901 1 INFO odoo werkzeug: 172.18.0.1 - - [22/May/2025 05:04:03] "GET /favicon.ico HTTP/1.1" 500 - 2 0.002 0.008
2025-05-22 05:04:57,546 1 ERROR odoo odoo.sql_db: bad query: b"\n            SELECT latest_version\n            FROM ir_module_module\n             WHERE name='base'\n        "
ERROR: relation "ir_module_module" does not exist
LINE 3:             FROM ir_module_module
                         ^
 
2025-05-22 05:04:57,547 1 WARNING odoo odoo.addons.base.models.ir_cron: Tried to poll an undefined table on database odoo. 
2025-05-22 05:05:00,930 1 ERROR odoo odoo.sql_db: bad query: b"\n            SELECT latest_version\n            FROM ir_module_module\n             WHERE name='base'\n        "
ERROR: relation "ir_module_module" does not exist
LINE 3:             FROM ir_module_module
                         ^
 
2025-05-22 05:05:00,931 1 WARNING odoo odoo.addons.base.models.ir_cron: Tried to poll an undefined table on database odoo. 
2025-05-22 05:05:54,593 1 INFO ? odoo.service.server: Initiating shutdown 
2025-05-22 05:05:54,594 1 INFO ? odoo.service.server: Hit CTRL-C again or send a second signal to force the shutdown. 
2025-05-22 05:05:54,601 1 INFO odoo odoo.sql_db: Connection to the database failed 
2025-05-22 05:05:54,601 1 WARNING odoo odoo.addons.base.models.ir_cron: Exception in cron: 
Traceback (most recent call last):
  File "/usr/lib/python3/dist-packages/odoo/addons/base/models/ir_cron.py", line 132, in _process_jobs
    with db.cursor() as cron_cr:
         ^^^^^^^^^^^
  File "/usr/lib/python3/dist-packages/odoo/sql_db.py", line 796, in cursor
    return Cursor(self.__pool, self.__dbname, self.__dsn)
           ^^^^^^^^^^^^^^^^^^^^^^^^^^^^^^^^^^^^^^^^^^^^^^
  File "/usr/lib/python3/dist-packages/odoo/sql_db.py", line 288, in __init__
    self._cnx = pool.borrow(dsn)
                ^^^^^^^^^^^^^^^^
  File "/usr/lib/python3/dist-packages/decorator.py", line 232, in fun
    return caller(func, *(extras + args), **kw)
           ^^^^^^^^^^^^^^^^^^^^^^^^^^^^^^^^^^^^
  File "/usr/lib/python3/dist-packages/odoo/tools/func.py", line 97, in locked
    return func(inst, *args, **kwargs)
           ^^^^^^^^^^^^^^^^^^^^^^^^^^^
  File "/usr/lib/python3/dist-packages/odoo/sql_db.py", line 723, in borrow
    result = psycopg2.connect(
             ^^^^^^^^^^^^^^^^^
  File "/usr/lib/python3/dist-packages/psycopg2/__init__.py", line 122, in connect
    conn = _connect(dsn, connection_factory=connection_factory, **kwasync)
           ^^^^^^^^^^^^^^^^^^^^^^^^^^^^^^^^^^^^^^^^^^^^^^^^^^^^^^^^^^^^^^^
psycopg2.OperationalError: connection to server at "db" (172.18.0.2), port 5432 failed: FATAL:  the database system is shutting down

2025-05-22 05:05:54,608 1 INFO odoo odoo.sql_db: Connection to the database failed 
2025-05-22 05:05:54,609 1 WARNING odoo odoo.addons.base.models.ir_cron: Exception in cron: 
Traceback (most recent call last):
  File "/usr/lib/python3/dist-packages/odoo/addons/base/models/ir_cron.py", line 132, in _process_jobs
    with db.cursor() as cron_cr:
         ^^^^^^^^^^^
  File "/usr/lib/python3/dist-packages/odoo/sql_db.py", line 796, in cursor
    return Cursor(self.__pool, self.__dbname, self.__dsn)
           ^^^^^^^^^^^^^^^^^^^^^^^^^^^^^^^^^^^^^^^^^^^^^^
  File "/usr/lib/python3/dist-packages/odoo/sql_db.py", line 288, in __init__
    self._cnx = pool.borrow(dsn)
                ^^^^^^^^^^^^^^^^
  File "/usr/lib/python3/dist-packages/decorator.py", line 232, in fun
    return caller(func, *(extras + args), **kw)
           ^^^^^^^^^^^^^^^^^^^^^^^^^^^^^^^^^^^^
  File "/usr/lib/python3/dist-packages/odoo/tools/func.py", line 97, in locked
    return func(inst, *args, **kwargs)
           ^^^^^^^^^^^^^^^^^^^^^^^^^^^
  File "/usr/lib/python3/dist-packages/odoo/sql_db.py", line 723, in borrow
    result = psycopg2.connect(
             ^^^^^^^^^^^^^^^^^
  File "/usr/lib/python3/dist-packages/psycopg2/__init__.py", line 122, in connect
    conn = _connect(dsn, connection_factory=connection_factory, **kwasync)
           ^^^^^^^^^^^^^^^^^^^^^^^^^^^^^^^^^^^^^^^^^^^^^^^^^^^^^^^^^^^^^^^
psycopg2.OperationalError: connection to server at "db" (172.18.0.2), port 5432 failed: FATAL:  the database system is shutting down

2025-05-22 05:05:54,896 1 INFO ? odoo.sql_db: ConnectionPool(read/write;used=0/count=0/max=64): Closed 1 connections  
2025-05-22 05:05:56,324 1 INFO ? odoo: Odoo version 18.0-20250520 
2025-05-22 05:05:56,325 1 INFO ? odoo: Using configuration file at /etc/odoo/odoo.conf 
2025-05-22 05:05:56,326 1 INFO ? odoo: addons paths: ['/usr/lib/python3/dist-packages/odoo/addons', '/var/lib/odoo/addons/18.0', '/mnt/extra-addons'] 
2025-05-22 05:05:56,326 1 INFO ? odoo: database: odoo@db:5432 
2025-05-22 05:05:56,500 1 INFO ? odoo.addons.base.models.ir_actions_report: Will use the Wkhtmltopdf binary at /usr/local/bin/wkhtmltopdf 
2025-05-22 05:05:56,506 1 INFO ? odoo.addons.base.models.ir_actions_report: Will use the Wkhtmltoimage binary at /usr/local/bin/wkhtmltoimage 
2025-05-22 05:05:56,630 1 INFO ? odoo.service.server: HTTP service (werkzeug) running on 4ce19f4768cc:8069 
2025-05-22 05:06:48,649 1 ERROR ? odoo.modules.loading: Database odoo not initialized, you can force it with `-i base` 
2025-05-22 05:06:48,649 1 INFO ? odoo.modules.registry: Registry loaded in 0.014s 
2025-05-22 05:06:48,651 1 ERROR odoo odoo.http: Exception during request handling. 
Traceback (most recent call last):
  File "/usr/lib/python3/dist-packages/odoo/http.py", line 2386, in __call__
    response = request._serve_db()
               ^^^^^^^^^^^^^^^^^^^
  File "/usr/lib/python3/dist-packages/odoo/http.py", line 1894, in _serve_db
    rule, args = self.registry['ir.http']._match(self.httprequest.path)
                 ~~~~~~~~~~~~~^^^^^^^^^^^
  File "/usr/lib/python3/dist-packages/odoo/modules/registry.py", line 240, in __getitem__
    return self.models[model_name]
           ~~~~~~~~~~~^^^^^^^^^^^^
KeyError: 'ir.http'
2025-05-22 05:06:48,653 1 INFO odoo werkzeug: 172.18.0.1 - - [22/May/2025 05:06:48] "GET / HTTP/1.1" 500 - 8 0.007 0.023
2025-05-22 05:06:48,693 1 ERROR odoo odoo.http: Exception during request handling. 
Traceback (most recent call last):
  File "/usr/lib/python3/dist-packages/odoo/http.py", line 2386, in __call__
    response = request._serve_db()
               ^^^^^^^^^^^^^^^^^^^
  File "/usr/lib/python3/dist-packages/odoo/http.py", line 1894, in _serve_db
    rule, args = self.registry['ir.http']._match(self.httprequest.path)
                 ~~~~~~~~~~~~~^^^^^^^^^^^
  File "/usr/lib/python3/dist-packages/odoo/modules/registry.py", line 240, in __getitem__
    return self.models[model_name]
           ~~~~~~~~~~~^^^^^^^^^^^^
KeyError: 'ir.http'
2025-05-22 05:06:48,694 1 INFO odoo werkzeug: 172.18.0.1 - - [22/May/2025 05:06:48] "GET /favicon.ico HTTP/1.1" 500 - 2 0.002 0.009
2025-05-22 05:06:59,318 1 ERROR odoo odoo.sql_db: bad query: b"\n            SELECT latest_version\n            FROM ir_module_module\n             WHERE name='base'\n        "
ERROR: relation "ir_module_module" does not exist
LINE 3:             FROM ir_module_module
                         ^
 
2025-05-22 05:06:59,319 1 WARNING odoo odoo.addons.base.models.ir_cron: Tried to poll an undefined table on database odoo. 
2025-05-22 05:07:00,335 1 ERROR odoo odoo.sql_db: bad query: b"\n            SELECT latest_version\n            FROM ir_module_module\n             WHERE name='base'\n        "
ERROR: relation "ir_module_module" does not exist
LINE 3:             FROM ir_module_module
                         ^
 
2025-05-22 05:07:00,336 1 WARNING odoo odoo.addons.base.models.ir_cron: Tried to poll an undefined table on database odoo. 
2025-05-22 05:07:14,179 1 INFO ? odoo.service.server: Initiating shutdown 
2025-05-22 05:07:14,180 1 INFO ? odoo.service.server: Hit CTRL-C again or send a second signal to force the shutdown. 
2025-05-22 05:07:14,445 1 INFO ? odoo.sql_db: ConnectionPool(read/write;used=0/count=0/max=64): Closed 3 connections  
2025-05-22 05:07:50,334 1 INFO ? odoo: Odoo version 18.0-20250520 
2025-05-22 05:07:50,335 1 INFO ? odoo: Using configuration file at /etc/odoo/odoo.conf 
2025-05-22 05:07:50,336 1 INFO ? odoo: addons paths: ['/usr/lib/python3/dist-packages/odoo/addons', '/var/lib/odoo/addons/18.0', '/mnt/extra-addons'] 
2025-05-22 05:07:50,336 1 INFO ? odoo: database: odoo@db:5432 
2025-05-22 05:07:50,514 1 INFO ? odoo.addons.base.models.ir_actions_report: Will use the Wkhtmltopdf binary at /usr/local/bin/wkhtmltopdf 
2025-05-22 05:07:50,520 1 INFO ? odoo.addons.base.models.ir_actions_report: Will use the Wkhtmltoimage binary at /usr/local/bin/wkhtmltoimage 
2025-05-22 05:07:50,676 1 INFO ? odoo.service.server: HTTP service (werkzeug) running on 4ce19f4768cc:8069 
2025-05-22 05:07:59,643 1 ERROR ? odoo.modules.loading: Database odoo not initialized, you can force it with `-i base` 
2025-05-22 05:07:59,644 1 INFO ? odoo.modules.registry: Registry loaded in 0.019s 
2025-05-22 05:07:59,645 1 ERROR odoo odoo.http: Exception during request handling. 
Traceback (most recent call last):
  File "/usr/lib/python3/dist-packages/odoo/http.py", line 2386, in __call__
    response = request._serve_db()
               ^^^^^^^^^^^^^^^^^^^
  File "/usr/lib/python3/dist-packages/odoo/http.py", line 1894, in _serve_db
    rule, args = self.registry['ir.http']._match(self.httprequest.path)
                 ~~~~~~~~~~~~~^^^^^^^^^^^
  File "/usr/lib/python3/dist-packages/odoo/modules/registry.py", line 240, in __getitem__
    return self.models[model_name]
           ~~~~~~~~~~~^^^^^^^^^^^^
KeyError: 'ir.http'
2025-05-22 05:07:59,647 1 INFO odoo werkzeug: 172.18.0.1 - - [22/May/2025 05:07:59] "GET / HTTP/1.1" 500 - 8 0.010 0.024
2025-05-22 05:07:59,684 1 ERROR odoo odoo.http: Exception during request handling. 
Traceback (most recent call last):
  File "/usr/lib/python3/dist-packages/odoo/http.py", line 2386, in __call__
    response = request._serve_db()
               ^^^^^^^^^^^^^^^^^^^
  File "/usr/lib/python3/dist-packages/odoo/http.py", line 1894, in _serve_db
    rule, args = self.registry['ir.http']._match(self.httprequest.path)
                 ~~~~~~~~~~~~~^^^^^^^^^^^
  File "/usr/lib/python3/dist-packages/odoo/modules/registry.py", line 240, in __getitem__
    return self.models[model_name]
           ~~~~~~~~~~~^^^^^^^^^^^^
KeyError: 'ir.http'
2025-05-22 05:07:59,684 1 INFO odoo werkzeug: 172.18.0.1 - - [22/May/2025 05:07:59] "GET /favicon.ico HTTP/1.1" 500 - 2 0.002 0.008
2025-05-22 05:08:00,943 1 ERROR odoo odoo.http: Exception during request handling. 
Traceback (most recent call last):
  File "/usr/lib/python3/dist-packages/odoo/http.py", line 2386, in __call__
    response = request._serve_db()
               ^^^^^^^^^^^^^^^^^^^
  File "/usr/lib/python3/dist-packages/odoo/http.py", line 1894, in _serve_db
    rule, args = self.registry['ir.http']._match(self.httprequest.path)
                 ~~~~~~~~~~~~~^^^^^^^^^^^
  File "/usr/lib/python3/dist-packages/odoo/modules/registry.py", line 240, in __getitem__
    return self.models[model_name]
           ~~~~~~~~~~~^^^^^^^^^^^^
KeyError: 'ir.http'
2025-05-22 05:08:00,944 1 INFO odoo werkzeug: 172.18.0.1 - - [22/May/2025 05:08:00] "GET / HTTP/1.1" 500 - 2 0.002 0.008
2025-05-22 05:08:00,967 1 ERROR odoo odoo.http: Exception during request handling. 
Traceback (most recent call last):
  File "/usr/lib/python3/dist-packages/odoo/http.py", line 2386, in __call__
    response = request._serve_db()
               ^^^^^^^^^^^^^^^^^^^
  File "/usr/lib/python3/dist-packages/odoo/http.py", line 1894, in _serve_db
    rule, args = self.registry['ir.http']._match(self.httprequest.path)
                 ~~~~~~~~~~~~~^^^^^^^^^^^
  File "/usr/lib/python3/dist-packages/odoo/modules/registry.py", line 240, in __getitem__
    return self.models[model_name]
           ~~~~~~~~~~~^^^^^^^^^^^^
KeyError: 'ir.http'
2025-05-22 05:08:00,968 1 INFO odoo werkzeug: 172.18.0.1 - - [22/May/2025 05:08:00] "GET /favicon.ico HTTP/1.1" 500 - 2 0.001 0.009
2025-05-22 05:08:01,333 1 ERROR odoo odoo.http: Exception during request handling. 
Traceback (most recent call last):
  File "/usr/lib/python3/dist-packages/odoo/http.py", line 2386, in __call__
    response = request._serve_db()
               ^^^^^^^^^^^^^^^^^^^
  File "/usr/lib/python3/dist-packages/odoo/http.py", line 1894, in _serve_db
    rule, args = self.registry['ir.http']._match(self.httprequest.path)
                 ~~~~~~~~~~~~~^^^^^^^^^^^
  File "/usr/lib/python3/dist-packages/odoo/modules/registry.py", line 240, in __getitem__
    return self.models[model_name]
           ~~~~~~~~~~~^^^^^^^^^^^^
KeyError: 'ir.http'
2025-05-22 05:08:01,334 1 INFO odoo werkzeug: 172.18.0.1 - - [22/May/2025 05:08:01] "GET / HTTP/1.1" 500 - 2 0.002 0.009
2025-05-22 05:08:01,357 1 ERROR odoo odoo.http: Exception during request handling. 
Traceback (most recent call last):
  File "/usr/lib/python3/dist-packages/odoo/http.py", line 2386, in __call__
    response = request._serve_db()
               ^^^^^^^^^^^^^^^^^^^
  File "/usr/lib/python3/dist-packages/odoo/http.py", line 1894, in _serve_db
    rule, args = self.registry['ir.http']._match(self.httprequest.path)
                 ~~~~~~~~~~~~~^^^^^^^^^^^
  File "/usr/lib/python3/dist-packages/odoo/modules/registry.py", line 240, in __getitem__
    return self.models[model_name]
           ~~~~~~~~~~~^^^^^^^^^^^^
KeyError: 'ir.http'
2025-05-22 05:08:01,358 1 INFO odoo werkzeug: 172.18.0.1 - - [22/May/2025 05:08:01] "GET /favicon.ico HTTP/1.1" 500 - 2 0.002 0.008
2025-05-22 05:08:01,488 1 ERROR odoo odoo.http: Exception during request handling. 
Traceback (most recent call last):
  File "/usr/lib/python3/dist-packages/odoo/http.py", line 2386, in __call__
    response = request._serve_db()
               ^^^^^^^^^^^^^^^^^^^
  File "/usr/lib/python3/dist-packages/odoo/http.py", line 1894, in _serve_db
    rule, args = self.registry['ir.http']._match(self.httprequest.path)
                 ~~~~~~~~~~~~~^^^^^^^^^^^
  File "/usr/lib/python3/dist-packages/odoo/modules/registry.py", line 240, in __getitem__
    return self.models[model_name]
           ~~~~~~~~~~~^^^^^^^^^^^^
KeyError: 'ir.http'
2025-05-22 05:08:01,489 1 INFO odoo werkzeug: 172.18.0.1 - - [22/May/2025 05:08:01] "GET / HTTP/1.1" 500 - 2 0.001 0.008
2025-05-22 05:08:01,509 1 ERROR odoo odoo.http: Exception during request handling. 
Traceback (most recent call last):
  File "/usr/lib/python3/dist-packages/odoo/http.py", line 2386, in __call__
    response = request._serve_db()
               ^^^^^^^^^^^^^^^^^^^
  File "/usr/lib/python3/dist-packages/odoo/http.py", line 1894, in _serve_db
    rule, args = self.registry['ir.http']._match(self.httprequest.path)
                 ~~~~~~~~~~~~~^^^^^^^^^^^
  File "/usr/lib/python3/dist-packages/odoo/modules/registry.py", line 240, in __getitem__
    return self.models[model_name]
           ~~~~~~~~~~~^^^^^^^^^^^^
KeyError: 'ir.http'
2025-05-22 05:08:01,510 1 INFO odoo werkzeug: 172.18.0.1 - - [22/May/2025 05:08:01] "GET /favicon.ico HTTP/1.1" 500 - 2 0.001 0.008
2025-05-22 05:08:01,648 1 ERROR odoo odoo.http: Exception during request handling. 
Traceback (most recent call last):
  File "/usr/lib/python3/dist-packages/odoo/http.py", line 2386, in __call__
    response = request._serve_db()
               ^^^^^^^^^^^^^^^^^^^
  File "/usr/lib/python3/dist-packages/odoo/http.py", line 1894, in _serve_db
    rule, args = self.registry['ir.http']._match(self.httprequest.path)
                 ~~~~~~~~~~~~~^^^^^^^^^^^
  File "/usr/lib/python3/dist-packages/odoo/modules/registry.py", line 240, in __getitem__
    return self.models[model_name]
           ~~~~~~~~~~~^^^^^^^^^^^^
KeyError: 'ir.http'
2025-05-22 05:08:01,649 1 INFO odoo werkzeug: 172.18.0.1 - - [22/May/2025 05:08:01] "GET / HTTP/1.1" 500 - 2 0.002 0.008
2025-05-22 05:08:01,721 1 ERROR odoo odoo.http: Exception during request handling. 
Traceback (most recent call last):
  File "/usr/lib/python3/dist-packages/odoo/http.py", line 2386, in __call__
    response = request._serve_db()
               ^^^^^^^^^^^^^^^^^^^
  File "/usr/lib/python3/dist-packages/odoo/http.py", line 1894, in _serve_db
    rule, args = self.registry['ir.http']._match(self.httprequest.path)
                 ~~~~~~~~~~~~~^^^^^^^^^^^
  File "/usr/lib/python3/dist-packages/odoo/modules/registry.py", line 240, in __getitem__
    return self.models[model_name]
           ~~~~~~~~~~~^^^^^^^^^^^^
KeyError: 'ir.http'
2025-05-22 05:08:01,722 1 INFO odoo werkzeug: 172.18.0.1 - - [22/May/2025 05:08:01] "GET /favicon.ico HTTP/1.1" 500 - 2 0.002 0.008
2025-05-22 05:08:01,812 1 ERROR odoo odoo.http: Exception during request handling. 
Traceback (most recent call last):
  File "/usr/lib/python3/dist-packages/odoo/http.py", line 2386, in __call__
    response = request._serve_db()
               ^^^^^^^^^^^^^^^^^^^
  File "/usr/lib/python3/dist-packages/odoo/http.py", line 1894, in _serve_db
    rule, args = self.registry['ir.http']._match(self.httprequest.path)
                 ~~~~~~~~~~~~~^^^^^^^^^^^
  File "/usr/lib/python3/dist-packages/odoo/modules/registry.py", line 240, in __getitem__
    return self.models[model_name]
           ~~~~~~~~~~~^^^^^^^^^^^^
KeyError: 'ir.http'
2025-05-22 05:08:01,813 1 INFO odoo werkzeug: 172.18.0.1 - - [22/May/2025 05:08:01] "GET / HTTP/1.1" 500 - 2 0.002 0.008
2025-05-22 05:08:01,834 1 ERROR odoo odoo.http: Exception during request handling. 
Traceback (most recent call last):
  File "/usr/lib/python3/dist-packages/odoo/http.py", line 2386, in __call__
    response = request._serve_db()
               ^^^^^^^^^^^^^^^^^^^
  File "/usr/lib/python3/dist-packages/odoo/http.py", line 1894, in _serve_db
    rule, args = self.registry['ir.http']._match(self.httprequest.path)
                 ~~~~~~~~~~~~~^^^^^^^^^^^
  File "/usr/lib/python3/dist-packages/odoo/modules/registry.py", line 240, in __getitem__
    return self.models[model_name]
           ~~~~~~~~~~~^^^^^^^^^^^^
KeyError: 'ir.http'
2025-05-22 05:08:01,835 1 INFO odoo werkzeug: 172.18.0.1 - - [22/May/2025 05:08:01] "GET /favicon.ico HTTP/1.1" 500 - 2 0.002 0.008
2025-05-22 05:08:01,980 1 ERROR odoo odoo.http: Exception during request handling. 
Traceback (most recent call last):
  File "/usr/lib/python3/dist-packages/odoo/http.py", line 2386, in __call__
    response = request._serve_db()
               ^^^^^^^^^^^^^^^^^^^
  File "/usr/lib/python3/dist-packages/odoo/http.py", line 1894, in _serve_db
    rule, args = self.registry['ir.http']._match(self.httprequest.path)
                 ~~~~~~~~~~~~~^^^^^^^^^^^
  File "/usr/lib/python3/dist-packages/odoo/modules/registry.py", line 240, in __getitem__
    return self.models[model_name]
           ~~~~~~~~~~~^^^^^^^^^^^^
KeyError: 'ir.http'
2025-05-22 05:08:01,981 1 INFO odoo werkzeug: 172.18.0.1 - - [22/May/2025 05:08:01] "GET / HTTP/1.1" 500 - 2 0.002 0.008
2025-05-22 05:08:02,001 1 ERROR odoo odoo.http: Exception during request handling. 
Traceback (most recent call last):
  File "/usr/lib/python3/dist-packages/odoo/http.py", line 2386, in __call__
    response = request._serve_db()
               ^^^^^^^^^^^^^^^^^^^
  File "/usr/lib/python3/dist-packages/odoo/http.py", line 1894, in _serve_db
    rule, args = self.registry['ir.http']._match(self.httprequest.path)
                 ~~~~~~~~~~~~~^^^^^^^^^^^
  File "/usr/lib/python3/dist-packages/odoo/modules/registry.py", line 240, in __getitem__
    return self.models[model_name]
           ~~~~~~~~~~~^^^^^^^^^^^^
KeyError: 'ir.http'
2025-05-22 05:08:02,002 1 INFO odoo werkzeug: 172.18.0.1 - - [22/May/2025 05:08:02] "GET /favicon.ico HTTP/1.1" 500 - 2 0.002 0.009
2025-05-22 05:08:02,147 1 ERROR odoo odoo.http: Exception during request handling. 
Traceback (most recent call last):
  File "/usr/lib/python3/dist-packages/odoo/http.py", line 2386, in __call__
    response = request._serve_db()
               ^^^^^^^^^^^^^^^^^^^
  File "/usr/lib/python3/dist-packages/odoo/http.py", line 1894, in _serve_db
    rule, args = self.registry['ir.http']._match(self.httprequest.path)
                 ~~~~~~~~~~~~~^^^^^^^^^^^
  File "/usr/lib/python3/dist-packages/odoo/modules/registry.py", line 240, in __getitem__
    return self.models[model_name]
           ~~~~~~~~~~~^^^^^^^^^^^^
KeyError: 'ir.http'
2025-05-22 05:08:02,148 1 INFO odoo werkzeug: 172.18.0.1 - - [22/May/2025 05:08:02] "GET / HTTP/1.1" 500 - 2 0.001 0.008
2025-05-22 05:08:02,169 1 ERROR odoo odoo.http: Exception during request handling. 
Traceback (most recent call last):
  File "/usr/lib/python3/dist-packages/odoo/http.py", line 2386, in __call__
    response = request._serve_db()
               ^^^^^^^^^^^^^^^^^^^
  File "/usr/lib/python3/dist-packages/odoo/http.py", line 1894, in _serve_db
    rule, args = self.registry['ir.http']._match(self.httprequest.path)
                 ~~~~~~~~~~~~~^^^^^^^^^^^
  File "/usr/lib/python3/dist-packages/odoo/modules/registry.py", line 240, in __getitem__
    return self.models[model_name]
           ~~~~~~~~~~~^^^^^^^^^^^^
KeyError: 'ir.http'
2025-05-22 05:08:02,170 1 INFO odoo werkzeug: 172.18.0.1 - - [22/May/2025 05:08:02] "GET /favicon.ico HTTP/1.1" 500 - 2 0.002 0.008
2025-05-22 05:08:02,333 1 ERROR odoo odoo.http: Exception during request handling. 
Traceback (most recent call last):
  File "/usr/lib/python3/dist-packages/odoo/http.py", line 2386, in __call__
    response = request._serve_db()
               ^^^^^^^^^^^^^^^^^^^
  File "/usr/lib/python3/dist-packages/odoo/http.py", line 1894, in _serve_db
    rule, args = self.registry['ir.http']._match(self.httprequest.path)
                 ~~~~~~~~~~~~~^^^^^^^^^^^
  File "/usr/lib/python3/dist-packages/odoo/modules/registry.py", line 240, in __getitem__
    return self.models[model_name]
           ~~~~~~~~~~~^^^^^^^^^^^^
KeyError: 'ir.http'
2025-05-22 05:08:02,334 1 INFO odoo werkzeug: 172.18.0.1 - - [22/May/2025 05:08:02] "GET / HTTP/1.1" 500 - 2 0.002 0.008
2025-05-22 05:08:02,356 1 ERROR odoo odoo.http: Exception during request handling. 
Traceback (most recent call last):
  File "/usr/lib/python3/dist-packages/odoo/http.py", line 2386, in __call__
    response = request._serve_db()
               ^^^^^^^^^^^^^^^^^^^
  File "/usr/lib/python3/dist-packages/odoo/http.py", line 1894, in _serve_db
    rule, args = self.registry['ir.http']._match(self.httprequest.path)
                 ~~~~~~~~~~~~~^^^^^^^^^^^
  File "/usr/lib/python3/dist-packages/odoo/modules/registry.py", line 240, in __getitem__
    return self.models[model_name]
           ~~~~~~~~~~~^^^^^^^^^^^^
KeyError: 'ir.http'
2025-05-22 05:08:02,357 1 INFO odoo werkzeug: 172.18.0.1 - - [22/May/2025 05:08:02] "GET /favicon.ico HTTP/1.1" 500 - 2 0.002 0.009
2025-05-22 05:08:51,399 1 INFO odoo odoo.sql_db: Connection to the database failed 
2025-05-22 05:08:51,400 1 WARNING odoo odoo.addons.base.models.ir_cron: Exception in cron: 
Traceback (most recent call last):
  File "/usr/lib/python3/dist-packages/odoo/addons/base/models/ir_cron.py", line 132, in _process_jobs
    with db.cursor() as cron_cr:
         ^^^^^^^^^^^
  File "/usr/lib/python3/dist-packages/odoo/sql_db.py", line 796, in cursor
    return Cursor(self.__pool, self.__dbname, self.__dsn)
           ^^^^^^^^^^^^^^^^^^^^^^^^^^^^^^^^^^^^^^^^^^^^^^
  File "/usr/lib/python3/dist-packages/odoo/sql_db.py", line 288, in __init__
    self._cnx = pool.borrow(dsn)
                ^^^^^^^^^^^^^^^^
  File "/usr/lib/python3/dist-packages/decorator.py", line 232, in fun
    return caller(func, *(extras + args), **kw)
           ^^^^^^^^^^^^^^^^^^^^^^^^^^^^^^^^^^^^
  File "/usr/lib/python3/dist-packages/odoo/tools/func.py", line 97, in locked
    return func(inst, *args, **kwargs)
           ^^^^^^^^^^^^^^^^^^^^^^^^^^^
  File "/usr/lib/python3/dist-packages/odoo/sql_db.py", line 723, in borrow
    result = psycopg2.connect(
             ^^^^^^^^^^^^^^^^^
  File "/usr/lib/python3/dist-packages/psycopg2/__init__.py", line 122, in connect
    conn = _connect(dsn, connection_factory=connection_factory, **kwasync)
           ^^^^^^^^^^^^^^^^^^^^^^^^^^^^^^^^^^^^^^^^^^^^^^^^^^^^^^^^^^^^^^^
psycopg2.OperationalError: connection to server at "db" (172.18.0.2), port 5432 failed: FATAL:  the database system is shutting down

2025-05-22 05:08:51,408 1 INFO odoo odoo.sql_db: Connection to the database failed 
2025-05-22 05:08:51,409 1 WARNING odoo odoo.addons.base.models.ir_cron: Exception in cron: 
Traceback (most recent call last):
  File "/usr/lib/python3/dist-packages/odoo/addons/base/models/ir_cron.py", line 132, in _process_jobs
    with db.cursor() as cron_cr:
         ^^^^^^^^^^^
  File "/usr/lib/python3/dist-packages/odoo/sql_db.py", line 796, in cursor
    return Cursor(self.__pool, self.__dbname, self.__dsn)
           ^^^^^^^^^^^^^^^^^^^^^^^^^^^^^^^^^^^^^^^^^^^^^^
  File "/usr/lib/python3/dist-packages/odoo/sql_db.py", line 288, in __init__
    self._cnx = pool.borrow(dsn)
                ^^^^^^^^^^^^^^^^
  File "/usr/lib/python3/dist-packages/decorator.py", line 232, in fun
    return caller(func, *(extras + args), **kw)
           ^^^^^^^^^^^^^^^^^^^^^^^^^^^^^^^^^^^^
  File "/usr/lib/python3/dist-packages/odoo/tools/func.py", line 97, in locked
    return func(inst, *args, **kwargs)
           ^^^^^^^^^^^^^^^^^^^^^^^^^^^
  File "/usr/lib/python3/dist-packages/odoo/sql_db.py", line 723, in borrow
    result = psycopg2.connect(
             ^^^^^^^^^^^^^^^^^
  File "/usr/lib/python3/dist-packages/psycopg2/__init__.py", line 122, in connect
    conn = _connect(dsn, connection_factory=connection_factory, **kwasync)
           ^^^^^^^^^^^^^^^^^^^^^^^^^^^^^^^^^^^^^^^^^^^^^^^^^^^^^^^^^^^^^^^
psycopg2.OperationalError: connection to server at "db" (172.18.0.2), port 5432 failed: FATAL:  the database system is shutting down

2025-05-22 05:08:57,942 1 INFO ? odoo.service.server: Initiating shutdown 
2025-05-22 05:08:57,942 1 INFO ? odoo.service.server: Hit CTRL-C again or send a second signal to force the shutdown. 
2025-05-22 05:08:58,005 1 INFO ? odoo.sql_db: ConnectionPool(read/write;used=0/count=0/max=64): Closed 1 connections  
2025-05-22 05:08:59,407 1 INFO ? odoo: Odoo version 18.0-20250520 
2025-05-22 05:08:59,408 1 INFO ? odoo: Using configuration file at /etc/odoo/odoo.conf 
2025-05-22 05:08:59,408 1 INFO ? odoo: addons paths: ['/usr/lib/python3/dist-packages/odoo/addons', '/var/lib/odoo/addons/18.0', '/mnt/extra-addons'] 
2025-05-22 05:08:59,408 1 INFO ? odoo: database: odoo@db:5432 
2025-05-22 05:08:59,583 1 INFO ? odoo.addons.base.models.ir_actions_report: Will use the Wkhtmltopdf binary at /usr/local/bin/wkhtmltopdf 
2025-05-22 05:08:59,589 1 INFO ? odoo.addons.base.models.ir_actions_report: Will use the Wkhtmltoimage binary at /usr/local/bin/wkhtmltoimage 
2025-05-22 05:08:59,721 1 INFO ? odoo.service.server: HTTP service (werkzeug) running on 4ce19f4768cc:8069 
2025-05-22 05:09:02,608 1 ERROR ? odoo.modules.loading: Database odoo not initialized, you can force it with `-i base` 
2025-05-22 05:09:02,609 1 INFO ? odoo.modules.registry: Registry loaded in 0.015s 
2025-05-22 05:09:02,610 1 ERROR odoo odoo.http: Exception during request handling. 
Traceback (most recent call last):
  File "/usr/lib/python3/dist-packages/odoo/http.py", line 2386, in __call__
    response = request._serve_db()
               ^^^^^^^^^^^^^^^^^^^
  File "/usr/lib/python3/dist-packages/odoo/http.py", line 1894, in _serve_db
    rule, args = self.registry['ir.http']._match(self.httprequest.path)
                 ~~~~~~~~~~~~~^^^^^^^^^^^
  File "/usr/lib/python3/dist-packages/odoo/modules/registry.py", line 240, in __getitem__
    return self.models[model_name]
           ~~~~~~~~~~~^^^^^^^^^^^^
KeyError: 'ir.http'
2025-05-22 05:09:02,612 1 INFO odoo werkzeug: 172.18.0.1 - - [22/May/2025 05:09:02] "GET / HTTP/1.1" 500 - 8 0.007 0.025
2025-05-22 05:09:02,648 1 ERROR odoo odoo.http: Exception during request handling. 
Traceback (most recent call last):
  File "/usr/lib/python3/dist-packages/odoo/http.py", line 2386, in __call__
    response = request._serve_db()
               ^^^^^^^^^^^^^^^^^^^
  File "/usr/lib/python3/dist-packages/odoo/http.py", line 1894, in _serve_db
    rule, args = self.registry['ir.http']._match(self.httprequest.path)
                 ~~~~~~~~~~~~~^^^^^^^^^^^
  File "/usr/lib/python3/dist-packages/odoo/modules/registry.py", line 240, in __getitem__
    return self.models[model_name]
           ~~~~~~~~~~~^^^^^^^^^^^^
KeyError: 'ir.http'
2025-05-22 05:09:02,649 1 INFO odoo werkzeug: 172.18.0.1 - - [22/May/2025 05:09:02] "GET /favicon.ico HTTP/1.1" 500 - 2 0.002 0.009
2025-05-22 05:09:14,193 1 INFO ? odoo.service.server: Initiating shutdown 
2025-05-22 05:09:14,194 1 INFO ? odoo.service.server: Hit CTRL-C again or send a second signal to force the shutdown. 
2025-05-22 05:09:14,384 1 INFO ? odoo.sql_db: ConnectionPool(read/write;used=0/count=0/max=64): Closed 3 connections  
2025-05-22 05:10:17,189 1 INFO ? odoo: Odoo version 18.0-20250520 
2025-05-22 05:10:17,190 1 INFO ? odoo: Using configuration file at /etc/odoo/odoo.conf 
2025-05-22 05:10:17,191 1 INFO ? odoo: addons paths: ['/usr/lib/python3/dist-packages/odoo/addons', '/var/lib/odoo/addons/18.0', '/mnt/extra-addons'] 
2025-05-22 05:10:17,191 1 INFO ? odoo: database: odoo@db:5432 
2025-05-22 05:10:17,368 1 INFO ? odoo.addons.base.models.ir_actions_report: Will use the Wkhtmltopdf binary at /usr/local/bin/wkhtmltopdf 
2025-05-22 05:10:17,374 1 INFO ? odoo.addons.base.models.ir_actions_report: Will use the Wkhtmltoimage binary at /usr/local/bin/wkhtmltoimage 
2025-05-22 05:10:17,513 1 INFO ? odoo.service.server: HTTP service (werkzeug) running on 0d2b6fa4fd1f:8069 
2025-05-22 05:11:23,025 1 ERROR ? odoo.modules.loading: Database odoo not initialized, you can force it with `-i base` 
2025-05-22 05:11:23,026 1 INFO ? odoo.modules.registry: Registry loaded in 0.012s 
2025-05-22 05:11:23,027 1 ERROR odoo odoo.http: Exception during request handling. 
Traceback (most recent call last):
  File "/usr/lib/python3/dist-packages/odoo/http.py", line 2386, in __call__
    response = request._serve_db()
               ^^^^^^^^^^^^^^^^^^^
  File "/usr/lib/python3/dist-packages/odoo/http.py", line 1894, in _serve_db
    rule, args = self.registry['ir.http']._match(self.httprequest.path)
                 ~~~~~~~~~~~~~^^^^^^^^^^^
  File "/usr/lib/python3/dist-packages/odoo/modules/registry.py", line 240, in __getitem__
    return self.models[model_name]
           ~~~~~~~~~~~^^^^^^^^^^^^
KeyError: 'ir.http'
2025-05-22 05:11:23,028 1 INFO odoo werkzeug: 172.18.0.1 - - [22/May/2025 05:11:23] "GET / HTTP/1.1" 500 - 8 0.006 0.018
2025-05-22 05:11:23,050 1 ERROR odoo odoo.http: Exception during request handling. 
Traceback (most recent call last):
  File "/usr/lib/python3/dist-packages/odoo/http.py", line 2386, in __call__
    response = request._serve_db()
               ^^^^^^^^^^^^^^^^^^^
  File "/usr/lib/python3/dist-packages/odoo/http.py", line 1894, in _serve_db
    rule, args = self.registry['ir.http']._match(self.httprequest.path)
                 ~~~~~~~~~~~~~^^^^^^^^^^^
  File "/usr/lib/python3/dist-packages/odoo/modules/registry.py", line 240, in __getitem__
    return self.models[model_name]
           ~~~~~~~~~~~^^^^^^^^^^^^
KeyError: 'ir.http'
2025-05-22 05:11:23,050 1 INFO odoo werkzeug: 172.18.0.1 - - [22/May/2025 05:11:23] "GET /favicon.ico HTTP/1.1" 500 - 2 0.002 0.009
2025-05-22 05:11:23,585 1 ERROR odoo odoo.http: Exception during request handling. 
Traceback (most recent call last):
  File "/usr/lib/python3/dist-packages/odoo/http.py", line 2386, in __call__
    response = request._serve_db()
               ^^^^^^^^^^^^^^^^^^^
  File "/usr/lib/python3/dist-packages/odoo/http.py", line 1894, in _serve_db
    rule, args = self.registry['ir.http']._match(self.httprequest.path)
                 ~~~~~~~~~~~~~^^^^^^^^^^^
  File "/usr/lib/python3/dist-packages/odoo/modules/registry.py", line 240, in __getitem__
    return self.models[model_name]
           ~~~~~~~~~~~^^^^^^^^^^^^
KeyError: 'ir.http'
2025-05-22 05:11:23,586 1 INFO odoo werkzeug: 172.18.0.1 - - [22/May/2025 05:11:23] "GET / HTTP/1.1" 500 - 2 0.002 0.008
2025-05-22 05:11:23,607 1 ERROR odoo odoo.http: Exception during request handling. 
Traceback (most recent call last):
  File "/usr/lib/python3/dist-packages/odoo/http.py", line 2386, in __call__
    response = request._serve_db()
               ^^^^^^^^^^^^^^^^^^^
  File "/usr/lib/python3/dist-packages/odoo/http.py", line 1894, in _serve_db
    rule, args = self.registry['ir.http']._match(self.httprequest.path)
                 ~~~~~~~~~~~~~^^^^^^^^^^^
  File "/usr/lib/python3/dist-packages/odoo/modules/registry.py", line 240, in __getitem__
    return self.models[model_name]
           ~~~~~~~~~~~^^^^^^^^^^^^
KeyError: 'ir.http'
2025-05-22 05:11:23,608 1 INFO odoo werkzeug: 172.18.0.1 - - [22/May/2025 05:11:23] "GET /favicon.ico HTTP/1.1" 500 - 2 0.002 0.009
2025-05-22 05:11:24,152 1 ERROR odoo odoo.http: Exception during request handling. 
Traceback (most recent call last):
  File "/usr/lib/python3/dist-packages/odoo/http.py", line 2386, in __call__
    response = request._serve_db()
               ^^^^^^^^^^^^^^^^^^^
  File "/usr/lib/python3/dist-packages/odoo/http.py", line 1894, in _serve_db
    rule, args = self.registry['ir.http']._match(self.httprequest.path)
                 ~~~~~~~~~~~~~^^^^^^^^^^^
  File "/usr/lib/python3/dist-packages/odoo/modules/registry.py", line 240, in __getitem__
    return self.models[model_name]
           ~~~~~~~~~~~^^^^^^^^^^^^
KeyError: 'ir.http'
2025-05-22 05:11:24,153 1 INFO odoo werkzeug: 172.18.0.1 - - [22/May/2025 05:11:24] "GET / HTTP/1.1" 500 - 2 0.002 0.008
2025-05-22 05:11:24,172 1 ERROR odoo odoo.http: Exception during request handling. 
Traceback (most recent call last):
  File "/usr/lib/python3/dist-packages/odoo/http.py", line 2386, in __call__
    response = request._serve_db()
               ^^^^^^^^^^^^^^^^^^^
  File "/usr/lib/python3/dist-packages/odoo/http.py", line 1894, in _serve_db
    rule, args = self.registry['ir.http']._match(self.httprequest.path)
                 ~~~~~~~~~~~~~^^^^^^^^^^^
  File "/usr/lib/python3/dist-packages/odoo/modules/registry.py", line 240, in __getitem__
    return self.models[model_name]
           ~~~~~~~~~~~^^^^^^^^^^^^
KeyError: 'ir.http'
2025-05-22 05:11:24,173 1 INFO odoo werkzeug: 172.18.0.1 - - [22/May/2025 05:11:24] "GET /favicon.ico HTTP/1.1" 500 - 2 0.001 0.008
2025-05-22 05:11:24,338 1 ERROR odoo odoo.http: Exception during request handling. 
Traceback (most recent call last):
  File "/usr/lib/python3/dist-packages/odoo/http.py", line 2386, in __call__
    response = request._serve_db()
               ^^^^^^^^^^^^^^^^^^^
  File "/usr/lib/python3/dist-packages/odoo/http.py", line 1894, in _serve_db
    rule, args = self.registry['ir.http']._match(self.httprequest.path)
                 ~~~~~~~~~~~~~^^^^^^^^^^^
  File "/usr/lib/python3/dist-packages/odoo/modules/registry.py", line 240, in __getitem__
    return self.models[model_name]
           ~~~~~~~~~~~^^^^^^^^^^^^
KeyError: 'ir.http'
2025-05-22 05:11:24,339 1 INFO odoo werkzeug: 172.18.0.1 - - [22/May/2025 05:11:24] "GET / HTTP/1.1" 500 - 2 0.002 0.008
2025-05-22 05:11:24,358 1 ERROR odoo odoo.http: Exception during request handling. 
Traceback (most recent call last):
  File "/usr/lib/python3/dist-packages/odoo/http.py", line 2386, in __call__
    response = request._serve_db()
               ^^^^^^^^^^^^^^^^^^^
  File "/usr/lib/python3/dist-packages/odoo/http.py", line 1894, in _serve_db
    rule, args = self.registry['ir.http']._match(self.httprequest.path)
                 ~~~~~~~~~~~~~^^^^^^^^^^^
  File "/usr/lib/python3/dist-packages/odoo/modules/registry.py", line 240, in __getitem__
    return self.models[model_name]
           ~~~~~~~~~~~^^^^^^^^^^^^
KeyError: 'ir.http'
2025-05-22 05:11:24,358 1 INFO odoo werkzeug: 172.18.0.1 - - [22/May/2025 05:11:24] "GET /favicon.ico HTTP/1.1" 500 - 2 0.002 0.009
2025-05-22 05:11:24,565 1 ERROR odoo odoo.http: Exception during request handling. 
Traceback (most recent call last):
  File "/usr/lib/python3/dist-packages/odoo/http.py", line 2386, in __call__
    response = request._serve_db()
               ^^^^^^^^^^^^^^^^^^^
  File "/usr/lib/python3/dist-packages/odoo/http.py", line 1894, in _serve_db
    rule, args = self.registry['ir.http']._match(self.httprequest.path)
                 ~~~~~~~~~~~~~^^^^^^^^^^^
  File "/usr/lib/python3/dist-packages/odoo/modules/registry.py", line 240, in __getitem__
    return self.models[model_name]
           ~~~~~~~~~~~^^^^^^^^^^^^
KeyError: 'ir.http'
2025-05-22 05:11:24,566 1 INFO odoo werkzeug: 172.18.0.1 - - [22/May/2025 05:11:24] "GET / HTTP/1.1" 500 - 2 0.002 0.008
2025-05-22 05:11:24,585 1 ERROR odoo odoo.http: Exception during request handling. 
Traceback (most recent call last):
  File "/usr/lib/python3/dist-packages/odoo/http.py", line 2386, in __call__
    response = request._serve_db()
               ^^^^^^^^^^^^^^^^^^^
  File "/usr/lib/python3/dist-packages/odoo/http.py", line 1894, in _serve_db
    rule, args = self.registry['ir.http']._match(self.httprequest.path)
                 ~~~~~~~~~~~~~^^^^^^^^^^^
  File "/usr/lib/python3/dist-packages/odoo/modules/registry.py", line 240, in __getitem__
    return self.models[model_name]
           ~~~~~~~~~~~^^^^^^^^^^^^
KeyError: 'ir.http'
2025-05-22 05:11:24,586 1 INFO odoo werkzeug: 172.18.0.1 - - [22/May/2025 05:11:24] "GET /favicon.ico HTTP/1.1" 500 - 2 0.001 0.008
2025-05-22 05:11:45,684 1 INFO ? odoo.service.server: Initiating shutdown 
2025-05-22 05:11:45,684 1 INFO ? odoo.service.server: Hit CTRL-C again or send a second signal to force the shutdown. 
2025-05-22 05:11:47,375 1 INFO ? odoo.sql_db: ConnectionPool(read/write;used=0/count=0/max=64): Closed 3 connections  
2025-05-22 05:14:25,843 1 INFO ? odoo: Odoo version 18.0-20250520 
2025-05-22 05:14:25,845 1 INFO ? odoo: Using configuration file at /etc/odoo/odoo.conf 
2025-05-22 05:14:25,845 1 INFO ? odoo: addons paths: ['/usr/lib/python3/dist-packages/odoo/addons', '/var/lib/odoo/addons/18.0', '/mnt/extra-addons'] 
2025-05-22 05:14:25,846 1 INFO ? odoo: database: odoo@db:5432 
2025-05-22 05:14:26,171 1 INFO ? odoo.addons.base.models.ir_actions_report: Will use the Wkhtmltopdf binary at /usr/local/bin/wkhtmltopdf 
2025-05-22 05:14:26,263 1 INFO ? odoo.addons.base.models.ir_actions_report: Will use the Wkhtmltoimage binary at /usr/local/bin/wkhtmltoimage 
2025-05-22 05:14:26,617 1 INFO ? odoo.service.server: HTTP service (werkzeug) running on 0d2b6fa4fd1f:8069 
2025-05-22 05:14:50,735 1 ERROR ? odoo.modules.loading: Database odoo not initialized, you can force it with `-i base` 
2025-05-22 05:14:50,736 1 INFO ? odoo.modules.registry: Registry loaded in 0.041s 
2025-05-22 05:14:50,737 1 ERROR odoo odoo.http: Exception during request handling. 
Traceback (most recent call last):
  File "/usr/lib/python3/dist-packages/odoo/http.py", line 2386, in __call__
    response = request._serve_db()
               ^^^^^^^^^^^^^^^^^^^
  File "/usr/lib/python3/dist-packages/odoo/http.py", line 1894, in _serve_db
    rule, args = self.registry['ir.http']._match(self.httprequest.path)
                 ~~~~~~~~~~~~~^^^^^^^^^^^
  File "/usr/lib/python3/dist-packages/odoo/modules/registry.py", line 240, in __getitem__
    return self.models[model_name]
           ~~~~~~~~~~~^^^^^^^^^^^^
KeyError: 'ir.http'
2025-05-22 05:14:50,740 1 INFO odoo werkzeug: 172.18.0.1 - - [22/May/2025 05:14:50] "GET / HTTP/1.1" 500 - 8 0.036 0.028
2025-05-22 05:14:50,779 1 ERROR odoo odoo.http: Exception during request handling. 
Traceback (most recent call last):
  File "/usr/lib/python3/dist-packages/odoo/http.py", line 2386, in __call__
    response = request._serve_db()
               ^^^^^^^^^^^^^^^^^^^
  File "/usr/lib/python3/dist-packages/odoo/http.py", line 1894, in _serve_db
    rule, args = self.registry['ir.http']._match(self.httprequest.path)
                 ~~~~~~~~~~~~~^^^^^^^^^^^
  File "/usr/lib/python3/dist-packages/odoo/modules/registry.py", line 240, in __getitem__
    return self.models[model_name]
           ~~~~~~~~~~~^^^^^^^^^^^^
KeyError: 'ir.http'
2025-05-22 05:14:50,780 1 INFO odoo werkzeug: 172.18.0.1 - - [22/May/2025 05:14:50] "GET /favicon.ico HTTP/1.1" 500 - 2 0.002 0.010
2025-05-22 05:15:27,569 1 ERROR odoo odoo.sql_db: bad query: b"\n            SELECT latest_version\n            FROM ir_module_module\n             WHERE name='base'\n        "
ERROR: relation "ir_module_module" does not exist
LINE 3:             FROM ir_module_module
                         ^
 
2025-05-22 05:15:27,569 1 WARNING odoo odoo.addons.base.models.ir_cron: Tried to poll an undefined table on database odoo. 
2025-05-22 05:15:28,579 1 ERROR odoo odoo.sql_db: bad query: b"\n            SELECT latest_version\n            FROM ir_module_module\n             WHERE name='base'\n        "
ERROR: relation "ir_module_module" does not exist
LINE 3:             FROM ir_module_module
                         ^
 
2025-05-22 05:15:28,580 1 WARNING odoo odoo.addons.base.models.ir_cron: Tried to poll an undefined table on database odoo. 
2025-05-22 05:16:28,853 1 ERROR odoo odoo.sql_db: bad query: b"\n            SELECT latest_version\n            FROM ir_module_module\n             WHERE name='base'\n        "
ERROR: relation "ir_module_module" does not exist
LINE 3:             FROM ir_module_module
                         ^
 
2025-05-22 05:16:28,854 1 WARNING odoo odoo.addons.base.models.ir_cron: Tried to poll an undefined table on database odoo. 
2025-05-22 05:16:30,875 1 ERROR odoo odoo.sql_db: bad query: b"\n            SELECT latest_version\n            FROM ir_module_module\n             WHERE name='base'\n        "
ERROR: relation "ir_module_module" does not exist
LINE 3:             FROM ir_module_module
                         ^
 
2025-05-22 05:16:30,875 1 WARNING odoo odoo.addons.base.models.ir_cron: Tried to poll an undefined table on database odoo. 
2025-05-22 05:17:30,034 1 ERROR odoo odoo.sql_db: bad query: b"\n            SELECT latest_version\n            FROM ir_module_module\n             WHERE name='base'\n        "
ERROR: relation "ir_module_module" does not exist
LINE 3:             FROM ir_module_module
                         ^
 
2025-05-22 05:17:30,035 1 WARNING odoo odoo.addons.base.models.ir_cron: Tried to poll an undefined table on database odoo. 
2025-05-22 05:17:33,022 1 ERROR odoo odoo.sql_db: bad query: b"\n            SELECT latest_version\n            FROM ir_module_module\n             WHERE name='base'\n        "
ERROR: relation "ir_module_module" does not exist
LINE 3:             FROM ir_module_module
                         ^
 
2025-05-22 05:17:33,022 1 WARNING odoo odoo.addons.base.models.ir_cron: Tried to poll an undefined table on database odoo. 
2025-05-22 05:18:31,348 1 ERROR odoo odoo.sql_db: bad query: b"\n            SELECT latest_version\n            FROM ir_module_module\n             WHERE name='base'\n        "
ERROR: relation "ir_module_module" does not exist
LINE 3:             FROM ir_module_module
                         ^
 
2025-05-22 05:18:31,349 1 WARNING odoo odoo.addons.base.models.ir_cron: Tried to poll an undefined table on database odoo. 
2025-05-22 05:18:35,391 1 ERROR odoo odoo.sql_db: bad query: b"\n            SELECT latest_version\n            FROM ir_module_module\n             WHERE name='base'\n        "
ERROR: relation "ir_module_module" does not exist
LINE 3:             FROM ir_module_module
                         ^
 
2025-05-22 05:18:35,392 1 WARNING odoo odoo.addons.base.models.ir_cron: Tried to poll an undefined table on database odoo. 
2025-05-22 05:19:30,451 1 INFO ? odoo.service.server: Initiating shutdown 
2025-05-22 05:19:30,451 1 INFO ? odoo.service.server: Hit CTRL-C again or send a second signal to force the shutdown. 
2025-05-22 05:19:30,460 1 INFO ? odoo.sql_db: ConnectionPool(read/write;used=0/count=0/max=64): Closed 3 connections  
2025-05-22 05:22:50,507 1 INFO ? odoo: Odoo version 18.0-20250520 
2025-05-22 05:22:50,508 1 INFO ? odoo: Using configuration file at /etc/odoo/odoo.conf 
2025-05-22 05:22:50,508 1 INFO ? odoo: addons paths: ['/usr/lib/python3/dist-packages/odoo/addons', '/var/lib/odoo/addons/18.0', '/mnt/extra-addons'] 
2025-05-22 05:22:50,509 1 INFO ? odoo: database: odoo@db:5432 
2025-05-22 05:22:50,688 1 INFO ? odoo.addons.base.models.ir_actions_report: Will use the Wkhtmltopdf binary at /usr/local/bin/wkhtmltopdf 
2025-05-22 05:22:50,695 1 INFO ? odoo.addons.base.models.ir_actions_report: Will use the Wkhtmltoimage binary at /usr/local/bin/wkhtmltoimage 
2025-05-22 05:22:50,834 1 INFO ? odoo.service.server: HTTP service (werkzeug) running on d51e953011c8:8069 
2025-05-22 05:23:02,184 1 INFO ? odoo.service.server: Initiating shutdown 
2025-05-22 05:23:02,185 1 INFO ? odoo.service.server: Hit CTRL-C again or send a second signal to force the shutdown. 
2025-05-22 05:23:02,495 1 INFO ? odoo.sql_db: ConnectionPool(read/write;used=0/count=0/max=64): Closed 2 connections  
2025-05-22 05:25:38,361 1 INFO ? odoo: Odoo version 18.0-20250520 
2025-05-22 05:25:38,362 1 INFO ? odoo: Using configuration file at /etc/odoo/odoo.conf 
2025-05-22 05:25:38,362 1 INFO ? odoo: addons paths: ['/usr/lib/python3/dist-packages/odoo/addons', '/var/lib/odoo/addons/18.0', '/mnt/extra-addons'] 
2025-05-22 05:25:38,362 1 INFO ? odoo: database: odoo@db:5432 
2025-05-22 05:25:38,541 1 INFO ? odoo.addons.base.models.ir_actions_report: Will use the Wkhtmltopdf binary at /usr/local/bin/wkhtmltopdf 
2025-05-22 05:25:38,547 1 INFO ? odoo.addons.base.models.ir_actions_report: Will use the Wkhtmltoimage binary at /usr/local/bin/wkhtmltoimage 
2025-05-22 05:25:38,680 1 INFO ? odoo.service.server: HTTP service (werkzeug) running on 78ad70eb0ae4:8069 
2025-05-22 05:27:08,517 1 ERROR ? odoo.modules.loading: Database odoo not initialized, you can force it with `-i base` 
2025-05-22 05:27:08,517 1 INFO ? odoo.modules.registry: Registry loaded in 0.022s 
2025-05-22 05:27:08,519 1 ERROR odoo odoo.http: Exception during request handling. 
Traceback (most recent call last):
  File "/usr/lib/python3/dist-packages/odoo/http.py", line 2386, in __call__
    response = request._serve_db()
               ^^^^^^^^^^^^^^^^^^^
  File "/usr/lib/python3/dist-packages/odoo/http.py", line 1894, in _serve_db
    rule, args = self.registry['ir.http']._match(self.httprequest.path)
                 ~~~~~~~~~~~~~^^^^^^^^^^^
  File "/usr/lib/python3/dist-packages/odoo/modules/registry.py", line 240, in __getitem__
    return self.models[model_name]
           ~~~~~~~~~~~^^^^^^^^^^^^
KeyError: 'ir.http'
2025-05-22 05:27:08,520 1 INFO odoo werkzeug: 172.18.0.1 - - [22/May/2025 05:27:08] "GET / HTTP/1.1" 500 - 20 0.011 0.029
2025-05-22 05:27:08,555 1 ERROR odoo odoo.http: Exception during request handling. 
Traceback (most recent call last):
  File "/usr/lib/python3/dist-packages/odoo/http.py", line 2386, in __call__
    response = request._serve_db()
               ^^^^^^^^^^^^^^^^^^^
  File "/usr/lib/python3/dist-packages/odoo/http.py", line 1894, in _serve_db
    rule, args = self.registry['ir.http']._match(self.httprequest.path)
                 ~~~~~~~~~~~~~^^^^^^^^^^^
  File "/usr/lib/python3/dist-packages/odoo/modules/registry.py", line 240, in __getitem__
    return self.models[model_name]
           ~~~~~~~~~~~^^^^^^^^^^^^
KeyError: 'ir.http'
2025-05-22 05:27:08,556 1 INFO odoo werkzeug: 172.18.0.1 - - [22/May/2025 05:27:08] "GET /favicon.ico HTTP/1.1" 500 - 2 0.002 0.009
2025-05-22 05:27:41,689 1 ERROR odoo odoo.sql_db: bad query: b"\n            SELECT latest_version\n            FROM ir_module_module\n             WHERE name='base'\n        "
ERROR: relation "ir_module_module" does not exist
LINE 3:             FROM ir_module_module
                         ^
 
2025-05-22 05:27:41,690 1 WARNING odoo odoo.addons.base.models.ir_cron: Tried to poll an undefined table on database odoo. 
2025-05-22 05:27:43,636 1 ERROR odoo odoo.sql_db: bad query: b"\n            SELECT latest_version\n            FROM ir_module_module\n             WHERE name='base'\n        "
ERROR: relation "ir_module_module" does not exist
LINE 3:             FROM ir_module_module
                         ^
 
2025-05-22 05:27:43,637 1 WARNING odoo odoo.addons.base.models.ir_cron: Tried to poll an undefined table on database odoo. 
2025-05-22 05:28:43,367 1 ERROR odoo odoo.sql_db: bad query: b"\n            SELECT latest_version\n            FROM ir_module_module\n             WHERE name='base'\n        "
ERROR: relation "ir_module_module" does not exist
LINE 3:             FROM ir_module_module
                         ^
 
2025-05-22 05:28:43,368 1 WARNING odoo odoo.addons.base.models.ir_cron: Tried to poll an undefined table on database odoo. 
2025-05-22 05:28:46,328 1 ERROR odoo odoo.sql_db: bad query: b"\n            SELECT latest_version\n            FROM ir_module_module\n             WHERE name='base'\n        "
ERROR: relation "ir_module_module" does not exist
LINE 3:             FROM ir_module_module
                         ^
 
2025-05-22 05:28:46,329 1 WARNING odoo odoo.addons.base.models.ir_cron: Tried to poll an undefined table on database odoo. 
2025-05-22 05:29:44,842 1 ERROR odoo odoo.sql_db: bad query: b"\n            SELECT latest_version\n            FROM ir_module_module\n             WHERE name='base'\n        "
ERROR: relation "ir_module_module" does not exist
LINE 3:             FROM ir_module_module
                         ^
 
2025-05-22 05:29:44,843 1 WARNING odoo odoo.addons.base.models.ir_cron: Tried to poll an undefined table on database odoo. 
2025-05-22 05:29:48,834 1 ERROR odoo odoo.sql_db: bad query: b"\n            SELECT latest_version\n            FROM ir_module_module\n             WHERE name='base'\n        "
ERROR: relation "ir_module_module" does not exist
LINE 3:             FROM ir_module_module
                         ^
 
2025-05-22 05:29:48,834 1 WARNING odoo odoo.addons.base.models.ir_cron: Tried to poll an undefined table on database odoo. 
2025-05-22 05:30:46,445 1 ERROR odoo odoo.sql_db: bad query: b"\n            SELECT latest_version\n            FROM ir_module_module\n             WHERE name='base'\n        "
ERROR: relation "ir_module_module" does not exist
LINE 3:             FROM ir_module_module
                         ^
 
2025-05-22 05:30:46,446 1 WARNING odoo odoo.addons.base.models.ir_cron: Tried to poll an undefined table on database odoo. 
2025-05-22 05:30:51,419 1 ERROR odoo odoo.sql_db: bad query: b"\n            SELECT latest_version\n            FROM ir_module_module\n             WHERE name='base'\n        "
ERROR: relation "ir_module_module" does not exist
LINE 3:             FROM ir_module_module
                         ^
 
2025-05-22 05:30:51,420 1 WARNING odoo odoo.addons.base.models.ir_cron: Tried to poll an undefined table on database odoo. 
2025-05-22 05:30:51,508 1 INFO ? odoo.service.server: Initiating shutdown 
2025-05-22 05:30:51,509 1 INFO ? odoo.service.server: Hit CTRL-C again or send a second signal to force the shutdown. 
2025-05-22 05:30:51,953 1 INFO ? odoo.sql_db: ConnectionPool(read/write;used=0/count=0/max=64): Closed 3 connections  
